<?xml version="1.0" ?>
<!-- =================================================================================== -->
<!-- |    This document was autogenerated by xacro from src/lux_description/urdf/lux.urdf.xacro | -->
<!-- |    EDITING THIS FILE BY HAND IS NOT RECOMMENDED                                 | -->
<!-- =================================================================================== -->
<robot name="lux">
  <material name="orange">
    <color rgba="1.0 0.5 0.0 1.0"/>
  </material>
  <material name="black">
    <color rgba="0.1 0.1 0.1 1.0"/>
  </material>
  <material name="grey">
    <color rgba="0.6 0.6 0.6 1.0"/>
  </material>
  <!-- Root -->
  <link name="base_link"/>
  <link name="base_inertia">
    <visual>
      <origin rpy="0 0 0" xyz="0 0 0"/>
      <geometry>
        <mesh filename="package://lux_description/stl/body_frame.stl" scale="1 1 1"/>
      </geometry>
      <material name="orange"/>
    </visual>
    <collision>
      <origin rpy="0 0 0" xyz="0 0 0"/>
      <geometry>
        <box size="0.81 0.24 0.1"/>
      </geometry>
    </collision>
    <inertial>
      <origin rpy="0 0 0" xyz="0.001210 -0.000887 -0.007933"/>
      <mass value="3.092"/>
      <inertia ixx="0.012720949" ixy="0.000098785" ixz="-0.000130401" iyy="0.034500612" iyz="0.000097314" izz="0.043632308"/>
    </inertial>
  </link>
  <joint name="base_base" type="fixed">
    <origin rpy="0 0 0" xyz="0 0 0"/>
    <parent link="base_link"/>
    <child link="base_inertia"/>
  </joint>
  <link name="front_left_hip">
    <visual>
      <origin rpy="0 0 0" xyz="0 0 0"/>
      <geometry>
        <mesh filename="package://lux_description/stl/hip_1.stl" scale="1 1 1"/>
      </geometry>
      <material name="black"/>
    </visual>
    <collision>
      <origin rpy="0 0 0" xyz="0 0 0"/>
      <geometry>
        <box size="0.05 0.05 0.05"/>
      </geometry>
    </collision>
    <inertial>
      <origin rpy="0 0 0" xyz="-0.003 -0.000913 -0.000423"/>
      <mass value="0.421"/>
      <inertia ixx="0.000208442" ixy="-9.7e-07" ixz="3.59e-06" iyy="0.00034713" iyz="-2.271e-06" izz="0.000242004"/>
    </inertial>
  </link>
  <joint name="motor_front_left_hip" type="revolute">
    <axis xyz="1 0 0"/>
    <origin rpy="0 0 0" xyz="0.2025 0.06 0"/>
    <parent link="base_link"/>
    <child link="front_left_hip"/>
    <limit effort="40.0" lower="-1.04" upper="1.04" velocity="4.0"/>
    <dynamics damping="0.0" friction="0.0"/>
  </joint>
  <link name="front_left_upper_leg">
    <visual>
      <origin rpy="0 0 0" xyz="0 0 0"/>
      <geometry>
        <mesh filename="package://lux_description/stl/upper_leg_left.stl" scale="1 1 1"/>
      </geometry>
      <material name="black"/>
    </visual>
    <collision>
      <origin rpy="0 0 0" xyz="0 0 -0.105"/>
      <geometry>
        <cylinder length="0.21" radius="0.02"/>
      </geometry>
    </collision>
    <inertial>
      <origin rpy="0 0 0" xyz="0.00011 -0.017289 -0.042003"/>
      <mass value="0.823"/>
      <inertia ixx="0.004380506" ixy="1.19e-06" ixz="-3.916e-06" iyy="0.004394642" iyz="0.000544858" izz="0.000779349"/>
    </inertial>
  </link>
  <joint name="motor_front_left_upper_leg" type="revolute">
    <axis xyz="0 1 0"/>
    <origin rpy="0 0 0" xyz="0 0.0905 0"/>
    <parent link="front_left_hip"/>
    <child link="front_left_upper_leg"/>
    <limit effort="40.0" lower="-1.57079632679" upper="2.59" velocity="4.0"/>
    <dynamics damping="0.0" friction="0.0"/>
  </joint>
  <link name="front_left_lower_leg">
    <visual>
      <origin rpy="0 0 0" xyz="0 0 0"/>
      <geometry>
        <mesh filename="package://lux_description/stl/lower_leg_left.stl" scale="1 1 1"/>
      </geometry>
      <material name="black"/>
    </visual>
    <collision>
      <origin rpy="0 0 0" xyz="0 0 -0.105"/>
      <geometry>
        <cylinder length="0.21" radius="0.018"/>
      </geometry>
    </collision>
    <inertial>
      <origin rpy="0 0 0" xyz="-0.000176 0.0 -0.034133"/>
      <mass value="0.17"/>
      <inertia ixx="0.000604957" ixy="8e-09" ixz="2.77e-07" iyy="0.000622383" iyz="1.3e-08" izz="2.5776e-05"/>
    </inertial>
  </link>
  <joint name="motor_front_left_lower_leg" type="revolute">
    <axis xyz="0 1 0"/>
    <origin rpy="0 0 0" xyz="0 0 -0.21"/>
    <parent link="front_left_upper_leg"/>
    <child link="front_left_lower_leg"/>
    <limit effort="40.0" lower="-2.9" upper="1.57079632679" velocity="4.0"/>
    <dynamics damping="0.0" friction="0.0"/>
  </joint>
  <link name="front_left_foot">
    <visual>
      <origin rpy="0 0 0" xyz="0 0 0"/>
      <geometry>
        <sphere radius="0.025"/>
      </geometry>
      <material name="grey"/>
    </visual>
    <collision>
      <origin rpy="0 0 0" xyz="0 0 0"/>
      <geometry>
        <sphere radius="0.025"/>
      </geometry>
    </collision>
    <inertial>
      <origin rpy="0 0 0" xyz="0 0 0"/>
      <mass value="0.05"/>
      <inertia ixx="0.00005" ixy="0.0" ixz="0.0" iyy="0.00005" iyz="0.0" izz="0.00005"/>
    </inertial>
  </link>
  <joint name="front_left_leg_foot" type="fixed">
    <origin rpy="0 0 0" xyz="0 0 -0.21"/>
    <parent link="front_left_lower_leg"/>
    <child link="front_left_foot"/>
  </joint>
  <link name="front_right_hip">
    <visual>
      <origin rpy="0 0 0" xyz="0 0 0"/>
      <geometry>
        <mesh filename="package://lux_description/stl/hip_2.stl" scale="1 1 1"/>
      </geometry>
      <material name="black"/>
    </visual>
    <collision>
      <origin rpy="0 0 0" xyz="0 0 0"/>
      <geometry>
        <box size="0.05 0.05 0.05"/>
      </geometry>
    </collision>
    <inertial>
      <origin rpy="0 0 0" xyz="-0.003304 0.000913 -0.000118"/>
      <mass value="0.421"/>
      <inertia ixx="0.000208731" ixy="1.164e-06" ixz="3.22e-06" iyy="0.000346391" iyz="2.078e-06" izz="0.000240976"/>
    </inertial>
  </link>
  <joint name="motor_front_right_hip" type="revolute">
    <axis xyz="1 0 0"/>
    <origin rpy="0 0 0" xyz="0.2025 -0.06 0"/>
    <parent link="base_link"/>
    <child link="front_right_hip"/>
    <limit effort="40.0" lower="-1.04" upper="1.04" velocity="4.0"/>
    <dynamics damping="0.0" friction="0.0"/>
  </joint>
  <link name="front_right_upper_leg">
    <visual>
      <origin rpy="0 0 0" xyz="0 0 0"/>
      <geometry>
        <mesh filename="package://lux_description/stl/upper_leg_right.stl" scale="1 1 1"/>
      </geometry>
      <material name="black"/>
    </visual>
    <collision>
      <origin rpy="0 0 0" xyz="0 0 -0.105"/>
      <geometry>
        <cylinder length="0.21" radius="0.02"/>
      </geometry>
    </collision>
    <inertial>
      <origin rpy="0 0 0" xyz="-0.00011 0.017289 -0.042003"/>
      <mass value="0.823"/>
      <inertia ixx="0.004380506" ixy="1.19e-06" ixz="3.916e-06" iyy="0.004394642" iyz="-0.000544858" izz="0.000779349"/>
    </inertial>
  </link>
  <joint name="motor_front_right_upper_leg" type="revolute">
    <axis xyz="0 1 0"/>
    <origin rpy="0 0 0" xyz="0 -0.0905 0"/>
    <parent link="front_right_hip"/>
    <child link="front_right_upper_leg"/>
    <limit effort="40.0" lower="-1.57079632679" upper="2.59" velocity="4.0"/>
    <dynamics damping="0.0" friction="0.0"/>
  </joint>
  <link name="front_right_lower_leg">
    <visual>
      <origin rpy="0 0 0" xyz="0 0 0"/>
      <geometry>
        <mesh filename="package://lux_description/stl/lower_leg_right.stl" scale="1 1 1"/>
      </geometry>
      <material name="black"/>
    </visual>
    <collision>
      <origin rpy="0 0 0" xyz="0 0 -0.105"/>
      <geometry>
        <cylinder length="0.21" radius="0.018"/>
      </geometry>
    </collision>
    <inertial>
      <origin rpy="0 0 0" xyz="0.000176 0.0 -0.034133"/>
      <mass value="0.17"/>
      <inertia ixx="0.000604957" ixy="8e-09" ixz="-2.77e-07" iyy="0.000622383" iyz="-1.3e-08" izz="2.5776e-05"/>
    </inertial>
  </link>
  <joint name="motor_front_right_lower_leg" type="revolute">
    <axis xyz="0 1 0"/>
    <origin rpy="0 0 0" xyz="0 0 -0.21"/>
    <parent link="front_right_upper_leg"/>
    <child link="front_right_lower_leg"/>
    <limit effort="40.0" lower="-2.9" upper="1.57079632679" velocity="4.0"/>
    <dynamics damping="0.0" friction="0.0"/>
  </joint>
  <link name="front_right_foot">
    <visual>
      <origin rpy="0 0 0" xyz="0 0 0"/>
      <geometry>
        <sphere radius="0.025"/>
      </geometry>
      <material name="grey"/>
    </visual>
    <collision>
      <origin rpy="0 0 0" xyz="0 0 0"/>
      <geometry>
        <sphere radius="0.025"/>
      </geometry>
    </collision>
    <inertial>
      <origin rpy="0 0 0" xyz="0 0 0"/>
      <mass value="0.05"/>
      <inertia ixx="0.00005" ixy="0.0" ixz="0.0" iyy="0.00005" iyz="0.0" izz="0.00005"/>
    </inertial>
  </link>
  <joint name="front_right_leg_foot" type="fixed">
    <origin rpy="0 0 0" xyz="0 0 -0.21"/>
    <parent link="front_right_lower_leg"/>
    <child link="front_right_foot"/>
  </joint>
  <link name="back_left_hip">
    <visual>
      <origin rpy="0 0 0" xyz="0 0 0"/>
      <geometry>
        <mesh filename="package://lux_description/stl/hip_3.stl" scale="1 1 1"/>
      </geometry>
      <material name="black"/>
    </visual>
    <collision>
      <origin rpy="0 0 0" xyz="0 0 0"/>
      <geometry>
        <box size="0.05 0.05 0.05"/>
      </geometry>
    </collision>
    <inertial>
      <origin rpy="0 0 0" xyz="0.003304 -0.000713 -0.000118"/>
      <mass value="0.421"/>
      <inertia ixx="0.000208731" ixy="1.164e-06" ixz="-3.22e-06" iyy="0.000346392" iyz="-2.078e-06" izz="0.000240976"/>
    </inertial>
  </link>
  <joint name="motor_back_left_hip" type="revolute">
    <axis xyz="1 0 0"/>
    <origin rpy="0 0 0" xyz="-0.2025 0.06 0"/>
    <parent link="base_link"/>
    <child link="back_left_hip"/>
    <limit effort="40.0" lower="-1.04" upper="1.04" velocity="4.0"/>
    <dynamics damping="0.0" friction="0.0"/>
  </joint>
  <link name="back_left_upper_leg">
    <visual>
      <origin rpy="0 0 0" xyz="0 0 0"/>
      <geometry>
        <mesh filename="package://lux_description/stl/upper_leg_left.stl" scale="1 1 1"/>
      </geometry>
      <material name="black"/>
    </visual>
    <collision>
      <origin rpy="0 0 0" xyz="0 0 -0.105"/>
      <geometry>
        <cylinder length="0.21" radius="0.02"/>
      </geometry>
    </collision>
    <inertial>
      <origin rpy="0 0 0" xyz="0.00011 -0.017289 -0.042003"/>
      <mass value="0.823"/>
      <inertia ixx="0.004380506" ixy="1.19e-06" ixz="-3.916e-06" iyy="0.004394642" iyz="0.000544858" izz="0.000779349"/>
    </inertial>
  </link>
  <joint name="motor_back_left_upper_leg" type="revolute">
    <axis xyz="0 1 0"/>
    <origin rpy="0 0 0" xyz="0 0.0905 0"/>
    <parent link="back_left_hip"/>
    <child link="back_left_upper_leg"/>
    <limit effort="40.0" lower="-1.57079632679" upper="2.59" velocity="4.0"/>
    <dynamics damping="0.0" friction="0.0"/>
  </joint>
  <link name="back_left_lower_leg">
    <visual>
      <origin rpy="0 0 0" xyz="0 0 0"/>
      <geometry>
        <mesh filename="package://lux_description/stl/lower_leg_left.stl" scale="1 1 1"/>
      </geometry>
      <material name="black"/>
    </visual>
    <collision>
      <origin rpy="0 0 0" xyz="0 0 -0.105"/>
      <geometry>
        <cylinder length="0.21" radius="0.018"/>
      </geometry>
    </collision>
    <inertial>
      <origin rpy="0 0 0" xyz="-0.000176 0.0 -0.034133"/>
      <mass value="0.17"/>
      <inertia ixx="0.000604957" ixy="8e-09" ixz="2.77e-07" iyy="0.000622383" iyz="1.3e-08" izz="2.5776e-05"/>
    </inertial>
  </link>
  <joint name="motor_back_left_lower_leg" type="revolute">
    <axis xyz="0 1 0"/>
    <origin rpy="0 0 0" xyz="0 0 -0.21"/>
    <parent link="back_left_upper_leg"/>
    <child link="back_left_lower_leg"/>
    <limit effort="40.0" lower="-2.9" upper="1.57079632679" velocity="4.0"/>
    <dynamics damping="0.0" friction="0.0"/>
  </joint>
  <link name="back_left_foot">
    <visual>
      <origin rpy="0 0 0" xyz="0 0 0"/>
      <geometry>
        <sphere radius="0.025"/>
      </geometry>
      <material name="grey"/>
    </visual>
    <collision>
      <origin rpy="0 0 0" xyz="0 0 0"/>
      <geometry>
        <sphere radius="0.025"/>
      </geometry>
    </collision>
    <inertial>
      <origin rpy="0 0 0" xyz="0 0 0"/>
      <mass value="0.05"/>
      <inertia ixx="0.00005" ixy="0.0" ixz="0.0" iyy="0.00005" iyz="0.0" izz="0.00005"/>
    </inertial>
  </link>
  <joint name="back_left_leg_foot" type="fixed">
    <origin rpy="0 0 0" xyz="0 0 -0.21"/>
    <parent link="back_left_lower_leg"/>
    <child link="back_left_foot"/>
  </joint>
  <link name="back_right_hip">
    <visual>
      <origin rpy="0 0 0" xyz="0 0 0"/>
      <geometry>
        <mesh filename="package://lux_description/stl/hip_4.stl" scale="1 1 1"/>
      </geometry>
      <material name="black"/>
    </visual>
    <collision>
      <origin rpy="0 0 0" xyz="0 0 0"/>
      <geometry>
        <box size="0.05 0.05 0.05"/>
      </geometry>
    </collision>
    <inertial>
      <origin rpy="0 0 0" xyz="0.003 0.001113 -0.000423"/>
      <mass value="0.421"/>
      <inertia ixx="0.000208442" ixy="-9.7e-07" ixz="-3.59e-06" iyy="0.00034713" iyz="2.271e-06" izz="0.000242004"/>
    </inertial>
  </link>
  <joint name="motor_back_right_hip" type="revolute">
    <axis xyz="1 0 0"/>
    <origin rpy="0 0 0" xyz="-0.2025 -0.06 0"/>
    <parent link="base_link"/>
    <child link="back_right_hip"/>
    <limit effort="40.0" lower="-1.04" upper="1.04" velocity="4.0"/>
    <dynamics damping="0.0" friction="0.0"/>
  </joint>
  <link name="back_right_upper_leg">
    <visual>
      <origin rpy="0 0 0" xyz="0 0 0"/>
      <geometry>
        <mesh filename="package://lux_description/stl/upper_leg_right.stl" scale="1 1 1"/>
      </geometry>
      <material name="black"/>
    </visual>
    <collision>
      <origin rpy="0 0 0" xyz="0 0 -0.105"/>
      <geometry>
        <cylinder length="0.21" radius="0.02"/>
      </geometry>
    </collision>
    <inertial>
      <origin rpy="0 0 0" xyz="-0.00011 0.017289 -0.042003"/>
      <mass value="0.823"/>
      <inertia ixx="0.004380506" ixy="1.19e-06" ixz="3.916e-06" iyy="0.004394642" iyz="-0.000544858" izz="0.000779349"/>
    </inertial>
  </link>
  <joint name="motor_back_right_upper_leg" type="revolute">
    <axis xyz="0 1 0"/>
    <origin rpy="0 0 0" xyz="0 -0.0905 0"/>
    <parent link="back_right_hip"/>
    <child link="back_right_upper_leg"/>
    <limit effort="40.0" lower="-1.57079632679" upper="2.59" velocity="4.0"/>
    <dynamics damping="0.0" friction="0.0"/>
  </joint>
  <link name="back_right_lower_leg">
    <visual>
      <origin rpy="0 0 0" xyz="0 0 0"/>
      <geometry>
        <mesh filename="package://lux_description/stl/lower_leg_right.stl" scale="1 1 1"/>
      </geometry>
      <material name="black"/>
    </visual>
    <collision>
      <origin rpy="0 0 0" xyz="0 0 -0.105"/>
      <geometry>
        <cylinder length="0.21" radius="0.018"/>
      </geometry>
    </collision>
    <inertial>
      <origin rpy="0 0 0" xyz="0.000176 0.0 -0.034133"/>
      <mass value="0.17"/>
      <inertia ixx="0.000604957" ixy="8e-09" ixz="-2.77e-07" iyy="0.000622383" iyz="-1.3e-08" izz="2.5776e-05"/>
    </inertial>
  </link>
  <joint name="motor_back_right_lower_leg" type="revolute">
    <axis xyz="0 1 0"/>
    <origin rpy="0 0 0" xyz="0 0 -0.21"/>
    <parent link="back_right_upper_leg"/>
    <child link="back_right_lower_leg"/>
    <limit effort="40.0" lower="-2.9" upper="1.57079632679" velocity="4.0"/>
    <dynamics damping="0.0" friction="0.0"/>
  </joint>
  <link name="back_right_foot">
    <visual>
      <origin rpy="0 0 0" xyz="0 0 0"/>
      <geometry>
        <sphere radius="0.025"/>
      </geometry>
      <material name="grey"/>
    </visual>
    <collision>
      <origin rpy="0 0 0" xyz="0 0 0"/>
      <geometry>
        <sphere radius="0.025"/>
      </geometry>
    </collision>
    <inertial>
      <origin rpy="0 0 0" xyz="0 0 0"/>
      <mass value="0.05"/>
      <inertia ixx="0.00005" ixy="0.0" ixz="0.0" iyy="0.00005" iyz="0.0" izz="0.00005"/>
    </inertial>
  </link>
  <joint name="back_right_leg_foot" type="fixed">
    <origin rpy="0 0 0" xyz="0 0 -0.21"/>
    <parent link="back_right_lower_leg"/>
    <child link="back_right_foot"/>
  </joint>
</robot>
